Workbook

Sheet 0. Overview & Methods
A1: Supplementary Workbook — Water Consumption Impact (WCI) Analysis
A2: Companion to: AI Data Centers and the Water Use Feedback Loop (submitted to Water Research)
A4: 1. Purpose of this Workbook
A5: This workbook contains the full input data, equations, intermediate calculations, and sensitivity analyses that support the ten-site Water Consumption Impact (WCI) assessment reported in the main manuscript (Section 6). Every numerical result shown in the paper's figures and tables can be reproduced by opening the corresponding sheet; every formula is live and will re-evaluate if an input is changed. The workbook is self-contained: no external links, no macros, and no hidden sheets.
A7: 2. Sheet Index
A8: Sheet | B8: Contents
A9: 0. Overview & Methods | B9: This sheet. Workbook purpose, sheet index, equations, variable definitions, data sources, colour legend, and reproducibility notes.
A10: 1. Inputs | B10: Raw site inputs (W, r, K, PF, population) for each of the ten data centres with source citations. Yellow cells are editable inputs; everything downstream recalculates automatically.
A11: 2. WCI Decomposition | B11: Three-factor decomposition WCI = (W/K) × r × PF for each site, with W/K, r, PF, WCI, and C_avg/K tabulated. Includes a six-tier risk classification (OVERLOAD / SEVERE / HIGH / MODERATE / LOW / MINIMAL).
A12: 3. Community Equivalence | B12: Translates consumptive water use C_avg into (i) annual household-equivalents at US average residential consumption (0.4146 ML/hh-yr) and (ii) the facility's share of total community water use.
A13: 4. Growth Projections | B13: Two growth scenarios projected year-by-year from 2024 to 2035: HIGH (24% CAGR, Microsoft observed) and MODERATE (13% CAGR, US national aggregate, Shehabi 2024). Reports the year in which each site crosses WCI = 100%.
A14: 5. Ranked Summary | B14: All sites ranked by WCI (descending) with the full set of decomposition, community-share, classification, and breach-year results on a single row per site. This sheet is the one-page reference.
A15: 6. Chart Data | B15: Tidy data tables feeding the manuscript figures (WCI by site, community share, decomposition stacks, growth curves, policy-lever effects). Each block is a standalone plottable range.
A16: 7. Policy Sensitivity | B16: Effect on WCI of three policy levers applied in isolation: SITING (W/K multiplier), TECHNOLOGY (target r), MANAGEMENT (target PF). Identifies the dominant lever for each site.
A18: 3. Equations
A19: Eq. (1) Water Consumption Impact | B19: WCI = C_peak / K = (W / K) × r × PF
A20: Eq. (2) Consumption (average day) | B20: C_avg = r × W
A21: Eq. (3) Consumption (peak day) | B21: C_peak = C_avg × PF
A22: Eq. (4) Household equivalence | B22: HH_equiv = (C_avg × 365.25) / H_avg, where H_avg = 0.4146 ML / household / year
A23: Eq. (5) Community share | B23: Share = C_avg / (pop × h_pc), where h_pc = 0.000303 ML / person / day
A24: Eq. (6) Growth projection | B24: WCI(t) = WCI(2024) × (1 + g)^t, t = 0, 1, …, 11
A25: Eq. (7) Policy lever — Siting | B25: WCI_site = (α × W/K) × r × PF, α = 0.75 (default)
A26: Eq. (8) Policy lever — Technology | B26: WCI_tech = (W/K) × min(r, r_target) × PF, r_target = 0.25 (default)
A27: Eq. (9) Policy lever — Management | B27: WCI_mgmt = (W/K) × r × min(PF, PF_target), PF_target = 2.0 (default)
A29: 4. Variable Definitions and Units
A30: Symbol | B30: Definition · Units · Notes
A31: W | B31: Total water withdrawal by the facility (ML/d). Converted from operator-reported volume; 1 MGD = 3.78541 ML/d.
A32: C | B32: Consumptive use: water permanently removed from the local supply by evaporation in cooling towers (ML/d).
A33: r | B33: Consumptive ratio, r = C/W. Site-specific for Google sites (from Environmental Report 2025, EY-assured); industry average 0.77 assumed otherwise.
A34: K | B34: Host public water system permitted delivery capacity (ML/d), from state environmental permits and utility annual reports.
A35: PF | B35: Peaking factor: peak-day to average-day consumption ratio. Site-specific where available; 2.5 (warm-climate default) or 4.5 (extreme demand) otherwise.
A36: C_avg | B36: Average-day consumptive water use, C_avg = r × W (ML/d).
A37: C_peak | B37: Peak-day consumptive water use, C_peak = C_avg × PF (ML/d).
A38: PUE | B38: Power Usage Effectiveness = total facility energy / IT energy. Reported for Google facilities (2024).
A39: pop | B39: Population served by the host public water system (persons).
A40: h_pc | B40: Per-capita residential water use = 80 gal/day = 0.000303 ML/person/day (USGS 2015 Circular 1441).
A41: H_avg | B41: Average annual household water consumption = 0.4146 ML/household/year (USGS 2015).
A42: g | B42: Compound annual growth rate of facility water demand (unitless). HIGH scenario: 0.24; MODERATE scenario: 0.13.
A44: 5. WCI Risk Classification Thresholds
A45: Tier | B45: Definition and interpretation
...

Sheet 1. Inputs
A1: Sheet 1 — Site Inputs
A2: Raw water-use and host-utility data for ten US data-centre sites. Yellow cells are editable inputs.
A4: Site | B4: State | C4: Operator | D4: W (ML/yr) | E4: W (MGD) | F4: W (ML/d) | G4: r (C/W) | H4: C_avg (ML/d) | I4: K (MGD) | J4: K (ML/d) | K4: PF | L4: C_peak (ML/d) | M4: Population served | N4: PUE (2024) | O4: Source | P4: Source URL | Q4: Notes
A5: Lebanon | B5: IN | C5: Meta | E5: 1.27 | F5: =E5*3.78541 -> 4.8074707 | G5: 0.77 | H5: =G5*F5 -> 3.7017524 | I5: 4.6 | J5: =I5*3.78541 -> 17.412886 | K5: 6.3 | L5: =H5*K5 -> 23.32104 | M5: 18000 | N5: — | O5: Han et al. 2026; Project Domino 2025 | P5: =HYPERLINK("https://lebanon.in.gov/wp-content/uploads/2025/01/Docket-25-35-Project-Domino-Devt-Plan-Staff-Report.pdf","Lebanon IN — City of Lebanon Project Domino staff report") -> Lebanon IN — City of Lebanon Project Domino staff report | Q5: Meta campus; r assumed at industry average; PF from permit application.
A6: Council Bluffs | B6: IA | C6: Google | D6: 5338.6 | F6: =D6/365.25 -> 14.61629 | G6: 0.716 | H6: =G6*F6 -> 10.465264 | I6: 30 | J6: =I6*3.78541 -> 113.5623 | K6: 6.5 | L6: =H6*K6 -> 68.024215 | M6: 63000 | N6: 1.09 | O6: Google Environmental Report 2025 (p. 110) | P6: =HYPERLINK("https://sustainability.google/reports/google-2025-environmental-report/","Google 2025 Environmental Report") -> Google 2025 Environmental Report | Q6: Two facilities (PUE 1.11/1.07). W=1,410.3 Mgal; C=1,010.2 Mgal. r=C/W.
A7: Mayes County | B7: OK | C7: Google | D7: 4195.4 | F7: =D7/365.25 -> 11.486379 | G7: 0.752 | H7: =G7*F7 -> 8.6377572 | I7: 10 | J7: =I7*3.78541 -> 37.8541 | K7: 2.5 | L7: =H7*K7 -> 21.594393 | M7: 41000 | N7: 1.11 | O7: Google Environmental Report 2025 (p. 110) | P7: =HYPERLINK("https://sustainability.google/reports/google-2025-environmental-report/","Google 2025 Environmental Report") -> Google 2025 Environmental Report | Q7: W=1,108.3 Mgal; C=833.2 Mgal. PF=2.5 (warm-climate default).
A8: The Dalles | B8: OR | C8: Google | D8: 1745.5 | F8: =D8/365.25 -> 4.7789185 | G8: 0.784 | H8: =G8*F8 -> 3.7466721 | I8: 4.5 | J8: =I8*3.78541 -> 17.034345 | K8: 2.21 | L8: =H8*K8 -> 8.2801454 | M8: 16000 | N8: 1.08 | O8: Google Environmental Report 2025 (p. 110) | P8: =HYPERLINK("https://sustainability.google/reports/google-2025-environmental-report/","Google 2025 Environmental Report") -> Google 2025 Environmental Report | Q8: Two facilities (PUE 1.10/1.06). W=461.1 Mgal; C=361.4 Mgal. PF from permit.
A9: Douglas County | B9: GA | C9: Google | D9: 1680.7 | F9: =D9/365.25 -> 4.6015058 | G9: 0.826 | H9: =G9*F9 -> 3.8008438 | I9: 8 | J9: =I9*3.78541 -> 30.28328 | K9: 2.5 | L9: =H9*K9 -> 9.5021095 | M9: 146000 | N9: 1.09 | O9: Google Environmental Report 2025 (p. 110) | P9: =HYPERLINK("https://sustainability.google/reports/google-2025-environmental-report/","Google 2025 Environmental Report") -> Google 2025 Environmental Report | Q9: W=444.1 Mgal (7.4 potable + 436.7 reclaimed); C=366.9 Mgal.
A10: Wisconsin Site | B10: WI | C10: Microsoft | E10: 0.023 | F10: =E10*3.78541 -> 0.08706443 | G10: 0.77 | H10: =G10*F10 -> 0.067039611 | I10: 2 | J10: =I10*3.78541 -> 7.57082 | K10: 30 | L10: =H10*K10 -> 2.0111883 | M10: 12000 | N10: — | O10: Wisconsin Public Radio 2025; Han et al. 2026 §3.1.2 | P10: =HYPERLINK("https://www.wpr.org/news/mount-pleasant-approves-site-plans-microsoft-data-center-expansion","WPR — Microsoft Mount Pleasant data centre expansion") -> WPR — Microsoft Mount Pleasant data centre expansion | Q10: Mount Pleasant / Racine County. 8.4 M gal/yr; peak-day ratio >30x average from WPR records; r assumed; PF as adopted in Han 2026.
A11: Botetourt County | B11: VA | C11: Google | E11: 2 | F11: =E11*3.78541 -> 7.57082 | G11: 0.77 | H11: =G11*F11 -> 5.8295314 | I11: 28 | J11: =I11*3.78541 -> 105.99148 | K11: 2.5 | L11: =H11*K11 -> 14.573829 | M11: 34000 | N11: — | O11: Google Botetourt County FAQ | P11: =HYPERLINK("https://www.botetourtva.gov/1023/Google-Data-Center-Water","Botetourt County — Google Data Center Water FAQ") -> Botetourt County — Google Data Center Water FAQ | Q11: Permitted 2 MGD; facility ramping; no PUE reported. r assumed.
A12: Memphis | B12: TN | C12: xAI | E12: 1 | F12: =E12*3.78541 -> 3.78541 | G12: 0.77 | H12: =G12*F12 -> 2.9147657 | I12: 258 | J12: =I12*3.78541 -> 976.63578 | K12: 4.5 | L12: =H12*K12 -> 13.116446 | M12: 630000 | N12: — | O12: GEAA 2025 | P12: =HYPERLINK("https://www.protectouraquifer.org/issues/xai-supercomputer","Protect Our Aquifer — xAI Supercomputer dossier") -> Protect Our Aquifer — xAI Supercomputer dossier | Q12: xAI Colossus facility. Host utility is Memphis Light, Gas & Water (258 MGD). r and PF assumed.
A13: Midlothian | B13: TX | C13: Google | D13: 836.6 | F13: =D13/365.25 -> 2.290486 | G13: 0.825 | H13: =G13*F13 -> 1.8896509 | I13: 36 | J13: =I13*3.78541 -> 136.27476 | K13: 2.5 | L13: =H13*K13 -> 4.7241273 | M13: 40000 | N13: — | O13: Google Environmental Report 2025 (p. 110) | P13: =HYPERLINK("https://sustainability.google/reports/google-2025-environmental-report/","Google 2025 Environmental Report") -> Google 2025 Environmental Report | Q13: W=221.0 Mgal; C=182.3 Mgal. City of Midlothian Water (36 MGD combined: Tayman 12 + Auger 24).
A14: Henderson | B14: NV | C14: Google | D14: 1362.7 | F14: =D14/365.25 -> 3.7308693 | G14: 0.576 | H14: =G14*F14 -> 2.1489807 | I14: 900 | J14: =I14*3.78541 -> 3406.869 | K14: 2.5 | L14: =H14*K14 -> 5.3724517 | M14: 320000 | N14: 1.09 | O14: Google Environmental Report 2025 (p. 110) | P14: =HYPERLINK("https://sustainability.google/reports/google-2025-environmental-report/","Google 2025 Environmental Report") -> Google 2025 Environmental Report | Q14: W=359.9 Mgal; C=207.4 Mgal. Low r reflects discharge reuse. Host is SNWA (900 MGD).
A16: Methodology Notes
A17: Unit conversions | D17: 1 MGD = 3.78541 ML/d (million gallons per day to megalitres per day). 1 M gal = 3.78541 ML.
A18: Consumptive ratio r | D18: r = C / W. For Google sites, r is computed directly from site-specific withdrawal and consumption reported in Google Environmental Report 2025 (p. 110-111, EY-assured). For non-Google sites, r = 0.77 is adopted as the industry average for evaporative cooling.
A19: Peaking factor PF | D19: Ratio of peak-day to average-day consumption. Site-specific where permit or utility records are available; otherwise 2.5 (warm-climate default) or 4.5 (extreme demand).
A20: Host utility capacity K | D20: Permitted delivery capacity in MGD, converted to ML/d. Sourced from state environmental permits and utility annual reports.
A21: Power Usage Effectiveness PUE | D21: Total facility energy divided by IT energy. Google reports per-facility PUE (2020-2024); fleet average = 1.09 in 2024. PUE is not publicly disclosed for non-Google operators.

Sheet 2. WCI Decomposition
A1: Sheet 2 — WCI Three-Factor Decomposition
A2: WCI = (W/K) × r × PF = C_peak / K. Risk class thresholds are defined in Sheet 0 §5.
A4: Site | B4: W/K (demand scale) | C4: r (consumptive ratio) | D4: PF (peaking factor) | E4: WCI | F4: WCI (%) | G4: C_avg / K | H4: C_avg/K (%) | I4: Classification | J4: Dominant factor | K4: Interpretation
A5: ='1. Inputs'!A5 -> Lebanon | B5: ='1. Inputs'!F5/'1. Inputs'!J5 -> 0.27608696 | C5: ='1. Inputs'!G5 -> 0.77 | D5: ='1. Inputs'!K5 -> 6.3 | E5: =B5*C5*D5 -> 1.3392978 | F5: =E5 -> 1.3392978 | G5: =B5*C5 -> 0.21258696 | H5: =G5 -> 0.21258696 | I5: =IF(E5>1,"OVERLOAD",IF(E5>0.5,"SEVERE",IF(E5>0.25,"HIGH",IF(E5>0.1,"MODERATE",IF(E5>0.05,"LOW","MINIMAL"))))) -> OVERLOAD | J5: =IF(MAX(B5,C5,D5/10)=B5,"W/K (scale)",IF(MAX(B5,C5,D5/10)=C5,"r (technology)","PF (peaking)")) -> r (technology) | K5: OVERLOAD: peak consumption exceeds entire utility capacity. Extreme peaking factor is the binding constraint.
A6: ='1. Inputs'!A6 -> Council Bluffs | B6: ='1. Inputs'!F6/'1. Inputs'!J6 -> 0.12870724 | C6: ='1. Inputs'!G6 -> 0.716 | D6: ='1. Inputs'!K6 -> 6.5 | E6: =B6*C6*D6 -> 0.5990035 | F6: =E6 -> 0.5990035 | G6: =B6*C6 -> 0.092154384 | H6: =G6 -> 0.092154384 | I6: =IF(E6>1,"OVERLOAD",IF(E6>0.5,"SEVERE",IF(E6>0.25,"HIGH",IF(E6>0.1,"MODERATE",IF(E6>0.05,"LOW","MINIMAL"))))) -> SEVERE | J6: =IF(MAX(B6,C6,D6/10)=B6,"W/K (scale)",IF(MAX(B6,C6,D6/10)=C6,"r (technology)","PF (peaking)")) -> r (technology) | K6: SEVERE: peak consumption claims 60% of utility capacity. Large facility footprint amplified by high PF.
A7: ='1. Inputs'!A7 -> Mayes County | B7: ='1. Inputs'!F7/'1. Inputs'!J7 -> 0.30343818 | C7: ='1. Inputs'!G7 -> 0.752 | D7: ='1. Inputs'!K7 -> 2.5 | E7: =B7*C7*D7 -> 0.57046378 | F7: =E7 -> 0.57046378 | G7: =B7*C7 -> 0.22818551 | H7: =G7 -> 0.22818551 | I7: =IF(E7>1,"OVERLOAD",IF(E7>0.5,"SEVERE",IF(E7>0.25,"HIGH",IF(E7>0.1,"MODERATE",IF(E7>0.05,"LOW","MINIMAL"))))) -> SEVERE | J7: =IF(MAX(B7,C7,D7/10)=B7,"W/K (scale)",IF(MAX(B7,C7,D7/10)=C7,"r (technology)","PF (peaking)")) -> r (technology) | K7: SEVERE: 57% of utility consumed. Rural Oklahoma utility; demand scale dominates.
A8: ='1. Inputs'!A8 -> The Dalles | B8: ='1. Inputs'!F8/'1. Inputs'!J8 -> 0.28054607 | C8: ='1. Inputs'!G8 -> 0.784 | D8: ='1. Inputs'!K8 -> 2.21 | E8: =B8*C8*D8 -> 0.48608534 | F8: =E8 -> 0.48608534 | G8: =B8*C8 -> 0.21994812 | H8: =G8 -> 0.21994812 | I8: =IF(E8>1,"OVERLOAD",IF(E8>0.5,"SEVERE",IF(E8>0.25,"HIGH",IF(E8>0.1,"MODERATE",IF(E8>0.05,"LOW","MINIMAL"))))) -> HIGH | J8: =IF(MAX(B8,C8,D8/10)=B8,"W/K (scale)",IF(MAX(B8,C8,D8/10)=C8,"r (technology)","PF (peaking)")) -> r (technology) | K8: HIGH: 49% of utility consumed. Small-city utility with a large facility on demand-scale basis.
A9: ='1. Inputs'!A9 -> Douglas County | B9: ='1. Inputs'!F9/'1. Inputs'!J9 -> 0.15194873 | C9: ='1. Inputs'!G9 -> 0.826 | D9: ='1. Inputs'!K9 -> 2.5 | E9: =B9*C9*D9 -> 0.31377412 | F9: =E9 -> 0.31377412 | G9: =B9*C9 -> 0.12550965 | H9: =G9 -> 0.12550965 | I9: =IF(E9>1,"OVERLOAD",IF(E9>0.5,"SEVERE",IF(E9>0.25,"HIGH",IF(E9>0.1,"MODERATE",IF(E9>0.05,"LOW","MINIMAL"))))) -> HIGH | J9: =IF(MAX(B9,C9,D9/10)=B9,"W/K (scale)",IF(MAX(B9,C9,D9/10)=C9,"r (technology)","PF (peaking)")) -> r (technology) | K9: HIGH: 31% consumed. Large county utility; arid climate drives high r.
A10: ='1. Inputs'!A10 -> Wisconsin Site | B10: ='1. Inputs'!F10/'1. Inputs'!J10 -> 0.0115 | C10: ='1. Inputs'!G10 -> 0.77 | D10: ='1. Inputs'!K10 -> 30 | E10: =B10*C10*D10 -> 0.26565 | F10: =E10 -> 0.26565 | G10: =B10*C10 -> 0.008855 | H10: =G10 -> 0.008855 | I10: =IF(E10>1,"OVERLOAD",IF(E10>0.5,"SEVERE",IF(E10>0.25,"HIGH",IF(E10>0.1,"MODERATE",IF(E10>0.05,"LOW","MINIMAL"))))) -> HIGH | J10: =IF(MAX(B10,C10,D10/10)=B10,"W/K (scale)",IF(MAX(B10,C10,D10/10)=C10,"r (technology)","PF (peaking)")) -> PF (peaking) | K10: HIGH: extreme PF = 30 drives 27% peak load despite very small average withdrawal.
A11: ='1. Inputs'!A11 -> Botetourt County | B11: ='1. Inputs'!F11/'1. Inputs'!J11 -> 0.071428571 | C11: ='1. Inputs'!G11 -> 0.77 | D11: ='1. Inputs'!K11 -> 2.5 | E11: =B11*C11*D11 -> 0.1375 | F11: =E11 -> 0.1375 | G11: =B11*C11 -> 0.055 | H11: =G11 -> 0.055 | I11: =IF(E11>1,"OVERLOAD",IF(E11>0.5,"SEVERE",IF(E11>0.25,"HIGH",IF(E11>0.1,"MODERATE",IF(E11>0.05,"LOW","MINIMAL"))))) -> MODERATE | J11: =IF(MAX(B11,C11,D11/10)=B11,"W/K (scale)",IF(MAX(B11,C11,D11/10)=C11,"r (technology)","PF (peaking)")) -> r (technology) | K11: MODERATE: 14%. Permitted 2 MGD against 28 MGD utility.
A12: ='1. Inputs'!A12 -> Memphis | B12: ='1. Inputs'!F12/'1. Inputs'!J12 -> 0.003875969 | C12: ='1. Inputs'!G12 -> 0.77 | D12: ='1. Inputs'!K12 -> 4.5 | E12: =B12*C12*D12 -> 0.013430233 | F12: =E12 -> 0.013430233 | G12: =B12*C12 -> 0.0029844961 | H12: =G12 -> 0.0029844961 | I12: =IF(E12>1,"OVERLOAD",IF(E12>0.5,"SEVERE",IF(E12>0.25,"HIGH",IF(E12>0.1,"MODERATE",IF(E12>0.05,"LOW","MINIMAL"))))) -> MINIMAL | J12: =IF(MAX(B12,C12,D12/10)=B12,"W/K (scale)",IF(MAX(B12,C12,D12/10)=C12,"r (technology)","PF (peaking)")) -> r (technology) | K12: LOW: 1.3%. Massive 258 MGD Memphis utility absorbs the facility load.
A13: ='1. Inputs'!A13 -> Midlothian | B13: ='1. Inputs'!F13/'1. Inputs'!J13 -> 0.016807852 | C13: ='1. Inputs'!G13 -> 0.825 | D13: ='1. Inputs'!K13 -> 2.5 | E13: =B13*C13*D13 -> 0.034666194 | F13: =E13 -> 0.034666194 | G13: =B13*C13 -> 0.013866478 | H13: =G13 -> 0.013866478 | I13: =IF(E13>1,"OVERLOAD",IF(E13>0.5,"SEVERE",IF(E13>0.25,"HIGH",IF(E13>0.1,"MODERATE",IF(E13>0.05,"LOW","MINIMAL"))))) -> MINIMAL | J13: =IF(MAX(B13,C13,D13/10)=B13,"W/K (scale)",IF(MAX(B13,C13,D13/10)=C13,"r (technology)","PF (peaking)")) -> r (technology) | K13: MINIMAL: 3.5%. Midlothian's 36 MGD system comfortably absorbs facility demand, though DC share of community use is notable given the small population.
A14: ='1. Inputs'!A14 -> Henderson | B14: ='1. Inputs'!F14/'1. Inputs'!J14 -> 0.0010951021 | C14: ='1. Inputs'!G14 -> 0.576 | D14: ='1. Inputs'!K14 -> 2.5 | E14: =B14*C14*D14 -> 0.001576947 | F14: =E14 -> 0.001576947 | G14: =B14*C14 -> 0.00063077879 | H14: =G14 -> 0.00063077879 | I14: =IF(E14>1,"OVERLOAD",IF(E14>0.5,"SEVERE",IF(E14>0.25,"HIGH",IF(E14>0.1,"MODERATE",IF(E14>0.05,"LOW","MINIMAL"))))) -> MINIMAL | J14: =IF(MAX(B14,C14,D14/10)=B14,"W/K (scale)",IF(MAX(B14,C14,D14/10)=C14,"r (technology)","PF (peaking)")) -> r (technology) | K14: MINIMAL: 0.2%. SNWA's 900 MGD system makes facility contribution negligible.
A16: Risk Classification Thresholds
A17: OVERLOAD | B17: WCI > 1.00 | E17: Peak-day consumption by the facility exceeds the entire permitted utility capacity.
A18: SEVERE | B18: 0.50 < WCI ≤ 1.00 | E18: More than half of utility capacity is claimed by the facility on the peak day.
A19: HIGH | B19: 0.25 < WCI ≤ 0.50 | E19: A quarter to a half of utility capacity consumed; growth headroom eliminated.
A20: MODERATE | B20: 0.10 < WCI ≤ 0.25 | E20: Noticeable but manageable; demand-side measures warranted.
A21: LOW | B21: 0.05 < WCI ≤ 0.10 | E21: Minor contribution to utility load; standard operational planning suffices.
A22: MINIMAL | B22: WCI ≤ 0.05 | E22: Negligible impact on utility; within routine variation.

Sheet 3. Community Equivalence
A1: Sheet 3 — Community Water Equivalence
A2: Translates facility consumption into household-equivalent and community-share terms.
A4: Site | B4: C_avg (ML/d) | C4: C_annual (ML/yr) | D4: Household equivalent | E4: Population served | F4: Per-capita use (ML/d) | G4: Community total (ML/d) | H4: DC / Community (%) | I4: DC equivalent residents | J4: Interpretation
A5: ='1. Inputs'!A5 -> Lebanon | B5: ='1. Inputs'!H5 -> 3.7017524 | C5: =B5*365.25 -> 1352.0651 | D5: =C5/0.4146 -> 3261.1314 | E5: ='1. Inputs'!M5 -> 18000 | F5: 0.000303 | G5: =E5*F5 -> 5.454 | H5: =B5/G5 -> 0.67872249 | I5: =B5/F5 -> 12217.005 | J5: Facility consumes water equivalent to 68% of the entire small-city community's residential demand.
A6: ='1. Inputs'!A6 -> Council Bluffs | B6: ='1. Inputs'!H6 -> 10.465264 | C6: =B6*365.25 -> 3822.4376 | D6: =C6/0.4146 -> 9219.5794 | E6: ='1. Inputs'!M6 -> 63000 | F6: 0.000303 | G6: =E6*F6 -> 19.089 | H6: =B6/G6 -> 0.54823531 | I6: =B6/F6 -> 34538.824 | J6: Equal to 55% of the 63,000-person community's residential water use.
A7: ='1. Inputs'!A7 -> Mayes County | B7: ='1. Inputs'!H7 -> 8.6377572 | C7: =B7*365.25 -> 3154.9408 | D7: =C7/0.4146 -> 7609.6015 | E7: ='1. Inputs'!M7 -> 41000 | F7: 0.000303 | G7: =E7*F7 -> 12.423 | H7: =B7/G7 -> 0.69530364 | I7: =B7/F7 -> 28507.449 | J7: Equal to 70% of the 41,000-person rural community's residential water use.
A8: ='1. Inputs'!A8 -> The Dalles | B8: ='1. Inputs'!H8 -> 3.7466721 | C8: =B8*365.25 -> 1368.472 | D8: =C8/0.4146 -> 3300.7043 | E8: ='1. Inputs'!M8 -> 16000 | F8: 0.000303 | G8: =E8*F8 -> 4.848 | H8: =B8/G8 -> 0.77282841 | I8: =B8/F8 -> 12365.255 | J8: Equal to 77% of a 16,000-person town's residential water use.
A9: ='1. Inputs'!A9 -> Douglas County | B9: ='1. Inputs'!H9 -> 3.8008438 | C9: =B9*365.25 -> 1388.2582 | D9: =C9/0.4146 -> 3348.4279 | E9: ='1. Inputs'!M9 -> 146000 | F9: 0.000303 | G9: =E9*F9 -> 44.238 | H9: =B9/G9 -> 0.085918075 | I9: =B9/F9 -> 12544.039 | J9: Equal to 9% of the 146,000-person county's residential water use.
A10: ='1. Inputs'!A10 -> Wisconsin Site | B10: ='1. Inputs'!H10 -> 0.067039611 | C10: =B10*365.25 -> 24.486218 | D10: =C10/0.4146 -> 59.05986 | E10: ='1. Inputs'!M10 -> 12000 | F10: 0.000303 | G10: =E10*F10 -> 3.636 | H10: =B10/G10 -> 0.018437737 | I10: =B10/F10 -> 221.25284 | J10: Equal to 2% of the community's residential water use (tiny facility; dominant stress is peaking).
A11: ='1. Inputs'!A11 -> Botetourt County | B11: ='1. Inputs'!H11 -> 5.8295314 | C11: =B11*365.25 -> 2129.2363 | D11: =C11/0.4146 -> 5135.64 | E11: ='1. Inputs'!M11 -> 34000 | F11: 0.000303 | G11: =E11*F11 -> 10.302 | H11: =B11/G11 -> 0.56586405 | I11: =B11/F11 -> 19239.378 | J11: Equal to 57% of the 34,000-person county's residential water use.
A12: ='1. Inputs'!A12 -> Memphis | B12: ='1. Inputs'!H12 -> 2.9147657 | C12: =B12*365.25 -> 1064.6182 | D12: =C12/0.4146 -> 2567.82 | E12: ='1. Inputs'!M12 -> 630000 | F12: 0.000303 | G12: =E12*F12 -> 190.89 | H12: =B12/G12 -> 0.015269347 | I12: =B12/F12 -> 9619.6888 | J12: Equal to 1.5% of the 630,000-person city's residential water use.
A13: ='1. Inputs'!A13 -> Midlothian | B13: ='1. Inputs'!H13 -> 1.8896509 | C13: =B13*365.25 -> 690.195 | D13: =C13/0.4146 -> 1664.725 | E13: ='1. Inputs'!M13 -> 40000 | F13: 0.000303 | G13: =E13*F13 -> 12.12 | H13: =B13/G13 -> 0.15591179 | I13: =B13/F13 -> 6236.4717 | J13: Equal to 15.6% of the 40,000-person city's residential water use.
A14: ='1. Inputs'!A14 -> Henderson | B14: ='1. Inputs'!H14 -> 2.1489807 | C14: =B14*365.25 -> 784.9152 | D14: =C14/0.4146 -> 1893.1867 | E14: ='1. Inputs'!M14 -> 320000 | F14: 0.000303 | G14: =E14*F14 -> 96.96 | H14: =B14/G14 -> 0.02216358 | I14: =B14/F14 -> 7092.3455 | J14: Equal to 2.2% of the 320,000-person metro area's residential water use.
A16: Constants
A17: Average US household water use | D17: 0.4146 ML/household/year | G17: USGS 2015 Circular 1441
A18: Per-capita residential use | D18: 0.000303 ML/person/day (≈ 80 gal/day) | G18: USGS 2015 Circular 1441

Sheet 4. Growth Projections
A1: Sheet 4 — Growth Projections to 2035
A2: WCI(t) = WCI(2024) × (1 + g)^t. Two scenarios: HIGH (24% CAGR, Microsoft observed) and MODERATE (13% CAGR, US aggregate, Shehabi 2024).
A4: Scenario Parameters
A5: HIGH scenario CAGR | B5: 0.24 | D5: Microsoft observed water CAGR 2022-2024 (12,076 → 18,564 ML).
A6: MODERATE scenario CAGR | B6: 0.13 | D6: US national data centre water growth 2014-2023 (21.2 → 66 BL), Shehabi 2024.
A8: Panel A — HIGH growth scenario
A9: Site | B9: WCI 2024 (base) | C9: 2024 | D9: 2025 | E9: 2026 | F9: 2027 | G9: 2028 | H9: 2029 | I9: 2030 | J9: 2031 | K9: 2032 | L9: 2033 | M9: 2034 | N9: 2035 | O9: Breach year (WCI > 100%)
A10: ='2. WCI Decomposition'!A5 -> Lebanon | B10: ='2. WCI Decomposition'!E5 -> 1.3392978 | C10: =$B10*(1+$B$5)^0 -> 1.3392978 | D10: =$B10*(1+$B$5)^1 -> 1.6607293 | E10: =$B10*(1+$B$5)^2 -> 2.0593043 | F10: =$B10*(1+$B$5)^3 -> 2.5535374 | G10: =$B10*(1+$B$5)^4 -> 3.1663863 | H10: =$B10*(1+$B$5)^5 -> 3.9263191 | I10: =$B10*(1+$B$5)^6 -> 4.8686357 | J10: =$B10*(1+$B$5)^7 -> 6.0371082 | K10: =$B10*(1+$B$5)^8 -> 7.4860142 | L10: =$B10*(1+$B$5)^9 -> 9.2826576 | M10: =$B10*(1+$B$5)^10 -> 11.510495 | N10: =$B10*(1+$B$5)^11 -> 14.273014 | O10: {=IFERROR(INDEX($C$9:$N$9,MATCH(TRUE(),INDEX(C10:N10>=1,0),0)),"—")} -> 2024
A11: ='2. WCI Decomposition'!A6 -> Council Bluffs | B11: ='2. WCI Decomposition'!E6 -> 0.5990035 | C11: =$B11*(1+$B$5)^0 -> 0.5990035 | D11: =$B11*(1+$B$5)^1 -> 0.74276433 | E11: =$B11*(1+$B$5)^2 -> 0.92102777 | F11: =$B11*(1+$B$5)^3 -> 1.1420744 | G11: =$B11*(1+$B$5)^4 -> 1.4161723 | H11: =$B11*(1+$B$5)^5 -> 1.7560537 | I11: =$B11*(1+$B$5)^6 -> 2.1775065 | J11: =$B11*(1+$B$5)^7 -> 2.7001081 | K11: =$B11*(1+$B$5)^8 -> 3.3481341 | L11: =$B11*(1+$B$5)^9 -> 4.1516862 | M11: =$B11*(1+$B$5)^10 -> 5.1480909 | N11: =$B11*(1+$B$5)^11 -> 6.3836327 | O11: {=IFERROR(INDEX($C$9:$N$9,MATCH(TRUE(),INDEX(C11:N11>=1,0),0)),"—")} -> 2027
A12: ='2. WCI Decomposition'!A7 -> Mayes County | B12: ='2. WCI Decomposition'!E7 -> 0.57046378 | C12: =$B12*(1+$B$5)^0 -> 0.57046378 | D12: =$B12*(1+$B$5)^1 -> 0.70737508 | E12: =$B12*(1+$B$5)^2 -> 0.8771451 | F12: =$B12*(1+$B$5)^3 -> 1.0876599 | G12: =$B12*(1+$B$5)^4 -> 1.3486983 | H12: =$B12*(1+$B$5)^5 -> 1.6723859 | I12: =$B12*(1+$B$5)^6 -> 2.0737585 | J12: =$B12*(1+$B$5)^7 -> 2.5714606 | K12: =$B12*(1+$B$5)^8 -> 3.1886111 | L12: =$B12*(1+$B$5)^9 -> 3.9538778 | M12: =$B12*(1+$B$5)^10 -> 4.9028084 | N12: =$B12*(1+$B$5)^11 -> 6.0794825 | O12: {=IFERROR(INDEX($C$9:$N$9,MATCH(TRUE(),INDEX(C12:N12>=1,0),0)),"—")} -> 2027
A13: ='2. WCI Decomposition'!A8 -> The Dalles | B13: ='2. WCI Decomposition'!E8 -> 0.48608534 | C13: =$B13*(1+$B$5)^0 -> 0.48608534 | D13: =$B13*(1+$B$5)^1 -> 0.60274583 | E13: =$B13*(1+$B$5)^2 -> 0.74740482 | F13: =$B13*(1+$B$5)^3 -> 0.92678198 | G13: =$B13*(1+$B$5)^4 -> 1.1492097 | H13: =$B13*(1+$B$5)^5 -> 1.42502 | I13: =$B13*(1+$B$5)^6 -> 1.7670248 | J13: =$B13*(1+$B$5)^7 -> 2.1911107 | K13: =$B13*(1+$B$5)^8 -> 2.7169773 | L13: =$B13*(1+$B$5)^9 -> 3.3690518 | M13: =$B13*(1+$B$5)^10 -> 4.1776243 | N13: =$B13*(1+$B$5)^11 -> 5.1802541 | O13: {=IFERROR(INDEX($C$9:$N$9,MATCH(TRUE(),INDEX(C13:N13>=1,0),0)),"—")} -> 2028
A14: ='2. WCI Decomposition'!A9 -> Douglas County | B14: ='2. WCI Decomposition'!E9 -> 0.31377412 | C14: =$B14*(1+$B$5)^0 -> 0.31377412 | D14: =$B14*(1+$B$5)^1 -> 0.38907991 | E14: =$B14*(1+$B$5)^2 -> 0.48245909 | F14: =$B14*(1+$B$5)^3 -> 0.59824927 | G14: =$B14*(1+$B$5)^4 -> 0.74182909 | H14: =$B14*(1+$B$5)^5 -> 0.91986807 | I14: =$B14*(1+$B$5)^6 -> 1.1406364 | J14: =$B14*(1+$B$5)^7 -> 1.4143891 | K14: =$B14*(1+$B$5)^8 -> 1.7538425 | L14: =$B14*(1+$B$5)^9 -> 2.1747648 | M14: =$B14*(1+$B$5)^10 -> 2.6967083 | N14: =$B14*(1+$B$5)^11 -> 3.3439183 | O14: {=IFERROR(INDEX($C$9:$N$9,MATCH(TRUE(),INDEX(C14:N14>=1,0),0)),"—")} -> 2030
A15: ='2. WCI Decomposition'!A10 -> Wisconsin Site | B15: ='2. WCI Decomposition'!E10 -> 0.26565 | C15: =$B15*(1+$B$5)^0 -> 0.26565 | D15: =$B15*(1+$B$5)^1 -> 0.329406 | E15: =$B15*(1+$B$5)^2 -> 0.40846344 | F15: =$B15*(1+$B$5)^3 -> 0.50649467 | G15: =$B15*(1+$B$5)^4 -> 0.62805339 | H15: =$B15*(1+$B$5)^5 -> 0.7787862 | I15: =$B15*(1+$B$5)^6 -> 0.96569489 | J15: =$B15*(1+$B$5)^7 -> 1.1974617 | K15: =$B15*(1+$B$5)^8 -> 1.4848525 | L15: =$B15*(1+$B$5)^9 -> 1.841217 | M15: =$B15*(1+$B$5)^10 -> 2.2831091 | N15: =$B15*(1+$B$5)^11 -> 2.8310553 | O15: {=IFERROR(INDEX($C$9:$N$9,MATCH(TRUE(),INDEX(C15:N15>=1,0),0)),"—")} -> 2031
A16: ='2. WCI Decomposition'!A11 -> Botetourt County | B16: ='2. WCI Decomposition'!E11 -> 0.1375 | C16: =$B16*(1+$B$5)^0 -> 0.1375 | D16: =$B16*(1+$B$5)^1 -> 0.1705 | E16: =$B16*(1+$B$5)^2 -> 0.21142 | F16: =$B16*(1+$B$5)^3 -> 0.2621608 | G16: =$B16*(1+$B$5)^4 -> 0.32507939 | H16: =$B16*(1+$B$5)^5 -> 0.40309845 | I16: =$B16*(1+$B$5)^6 -> 0.49984207 | J16: =$B16*(1+$B$5)^7 -> 0.61980417 | K16: =$B16*(1+$B$5)^8 -> 0.76855717 | L16: =$B16*(1+$B$5)^9 -> 0.95301089 | M16: =$B16*(1+$B$5)^10 -> 1.1817335 | N16: =$B16*(1+$B$5)^11 -> 1.4653495 | O16: {=IFERROR(INDEX($C$9:$N$9,MATCH(TRUE(),INDEX(C16:N16>=1,0),0)),"—")} -> 2034
A17: ='2. WCI Decomposition'!A12 -> Memphis | B17: ='2. WCI Decomposition'!E12 -> 0.013430233 | C17: =$B17*(1+$B$5)^0 -> 0.013430233 | D17: =$B17*(1+$B$5)^1 -> 0.016653488 | E17: =$B17*(1+$B$5)^2 -> 0.020650326 | F17: =$B17*(1+$B$5)^3 -> 0.025606404 | G17: =$B17*(1+$B$5)^4 -> 0.031751941 | H17: =$B17*(1+$B$5)^5 -> 0.039372406 | I17: =$B17*(1+$B$5)^6 -> 0.048821784 | J17: =$B17*(1+$B$5)^7 -> 0.060539012 | K17: =$B17*(1+$B$5)^8 -> 0.075068375 | L17: =$B17*(1+$B$5)^9 -> 0.093084785 | M17: =$B17*(1+$B$5)^10 -> 0.11542513 | N17: =$B17*(1+$B$5)^11 -> 0.14312717 | O17: {=IFERROR(INDEX($C$9:$N$9,MATCH(TRUE(),INDEX(C17:N17>=1,0),0)),"—")} -> —
A18: ='2. WCI Decomposition'!A13 -> Midlothian | B18: ='2. WCI Decomposition'!E13 -> 0.034666194 | C18: =$B18*(1+$B$5)^0 -> 0.034666194 | D18: =$B18*(1+$B$5)^1 -> 0.042986081 | E18: =$B18*(1+$B$5)^2 -> 0.05330274 | F18: =$B18*(1+$B$5)^3 -> 0.066095398 | G18: =$B18*(1+$B$5)^4 -> 0.081958294 | H18: =$B18*(1+$B$5)^5 -> 0.10162828 | I18: =$B18*(1+$B$5)^6 -> 0.12601907 | J18: =$B18*(1+$B$5)^7 -> 0.15626365 | K18: =$B18*(1+$B$5)^8 -> 0.19376693 | L18: =$B18*(1+$B$5)^9 -> 0.24027099 | M18: =$B18*(1+$B$5)^10 -> 0.29793602 | N18: =$B18*(1+$B$5)^11 -> 0.36944067 | O18: {=IFERROR(INDEX($C$9:$N$9,MATCH(TRUE(),INDEX(C18:N18>=1,0),0)),"—")} -> —
A19: ='2. WCI Decomposition'!A14 -> Henderson | B19: ='2. WCI Decomposition'!E14 -> 0.001576947 | C19: =$B19*(1+$B$5)^0 -> 0.001576947 | D19: =$B19*(1+$B$5)^1 -> 0.0019554142 | E19: =$B19*(1+$B$5)^2 -> 0.0024247137 | F19: =$B19*(1+$B$5)^3 -> 0.0030066449 | G19: =$B19*(1+$B$5)^4 -> 0.0037282397 | H19: =$B19*(1+$B$5)^5 -> 0.0046230173 | I19: =$B19*(1+$B$5)^6 -> 0.0057325414 | J19: =$B19*(1+$B$5)^7 -> 0.0071083513 | K19: =$B19*(1+$B$5)^8 -> 0.0088143557 | L19: =$B19*(1+$B$5)^9 -> 0.010929801 | M19: =$B19*(1+$B$5)^10 -> 0.013552953 | N19: =$B19*(1+$B$5)^11 -> 0.016805662 | O19: {=IFERROR(INDEX($C$9:$N$9,MATCH(TRUE(),INDEX(C19:N19>=1,0),0)),"—")} -> —
A21: Panel B — MODERATE growth scenario
A22: Site | B22: WCI 2024 (base) | C22: 2024 | D22: 2025 | E22: 2026 | F22: 2027 | G22: 2028 | H22: 2029 | I22: 2030 | J22: 2031 | K22: 2032 | L22: 2033 | M22: 2034 | N22: 2035 | O22: Breach year (WCI > 100%)
A23: ='2. WCI Decomposition'!A5 -> Lebanon | B23: ='2. WCI Decomposition'!E5 -> 1.3392978 | C23: =$B23*(1+$B$6)^0 -> 1.3392978 | D23: =$B23*(1+$B$6)^1 -> 1.5134065 | E23: =$B23*(1+$B$6)^2 -> 1.7101494 | F23: =$B23*(1+$B$6)^3 -> 1.9324688 | G23: =$B23*(1+$B$6)^4 -> 2.1836898 | H23: =$B23*(1+$B$6)^5 -> 2.4675694 | I23: =$B23*(1+$B$6)^6 -> 2.7883535 | J23: =$B23*(1+$B$6)^7 -> 3.1508394 | K23: =$B23*(1+$B$6)^8 -> 3.5604485 | L23: =$B23*(1+$B$6)^9 -> 4.0233068 | M23: =$B23*(1+$B$6)^10 -> 4.5463367 | N23: =$B23*(1+$B$6)^11 -> 5.1373605 | O23: {=IFERROR(INDEX($C$22:$N$22,MATCH(TRUE(),INDEX(C23:N23>=1,0),0)),"—")} -> 2024
A24: ='2. WCI Decomposition'!A6 -> Council Bluffs | B24: ='2. WCI Decomposition'!E6 -> 0.5990035 | C24: =$B24*(1+$B$6)^0 -> 0.5990035 | D24: =$B24*(1+$B$6)^1 -> 0.67687395 | E24: =$B24*(1+$B$6)^2 -> 0.76486756 | F24: =$B24*(1+$B$6)^3 -> 0.86430035 | G24: =$B24*(1+$B$6)^4 -> 0.97665939 | H24: =$B24*(1+$B$6)^5 -> 1.1036251 | I24: =$B24*(1+$B$6)^6 -> 1.2470964 | J24: =$B24*(1+$B$6)^7 -> 1.4092189 | K24: =$B24*(1+$B$6)^8 -> 1.5924174 | L24: =$B24*(1+$B$6)^9 -> 1.7994316 | M24: =$B24*(1+$B$6)^10 -> 2.0333577 | N24: =$B24*(1+$B$6)^11 -> 2.2976942 | O24: {=IFERROR(INDEX($C$22:$N$22,MATCH(TRUE(),INDEX(C24:N24>=1,0),0)),"—")} -> 2029
A25: ='2. WCI Decomposition'!A7 -> Mayes County | B25: ='2. WCI Decomposition'!E7 -> 0.57046378 | C25: =$B25*(1+$B$6)^0 -> 0.57046378 | D25: =$B25*(1+$B$6)^1 -> 0.64462407 | E25: =$B25*(1+$B$6)^2 -> 0.7284252 | F25: =$B25*(1+$B$6)^3 -> 0.82312047 | G25: =$B25*(1+$B$6)^4 -> 0.93012613 | H25: =$B25*(1+$B$6)^5 -> 1.0510425 | I25: =$B25*(1+$B$6)^6 -> 1.1876781 | J25: =$B25*(1+$B$6)^7 -> 1.3420762 | K25: =$B25*(1+$B$6)^8 -> 1.5165461 | L25: =$B25*(1+$B$6)^9 -> 1.7136971 | M25: =$B25*(1+$B$6)^10 -> 1.9364777 | N25: =$B25*(1+$B$6)^11 -> 2.1882198 | O25: {=IFERROR(INDEX($C$22:$N$22,MATCH(TRUE(),INDEX(C25:N25>=1,0),0)),"—")} -> 2029
A26: ='2. WCI Decomposition'!A8 -> The Dalles | B26: ='2. WCI Decomposition'!E8 -> 0.48608534 | C26: =$B26*(1+$B$6)^0 -> 0.48608534 | D26: =$B26*(1+$B$6)^1 -> 0.54927644 | E26: =$B26*(1+$B$6)^2 -> 0.62068237 | F26: =$B26*(1+$B$6)^3 -> 0.70137108 | G26: =$B26*(1+$B$6)^4 -> 0.79254932 | H26: =$B26*(1+$B$6)^5 -> 0.89558074 | I26: =$B26*(1+$B$6)^6 -> 1.0120062 | J26: =$B26*(1+$B$6)^7 -> 1.143567 | K26: =$B26*(1+$B$6)^8 -> 1.2922308 | L26: =$B26*(1+$B$6)^9 -> 1.4602208 | M26: =$B26*(1+$B$6)^10 -> 1.6500495 | N26: =$B26*(1+$B$6)^11 -> 1.8645559 | O26: {=IFERROR(INDEX($C$22:$N$22,MATCH(TRUE(),INDEX(C26:N26>=1,0),0)),"—")} -> 2030
A27: ='2. WCI Decomposition'!A9 -> Douglas County | B27: ='2. WCI Decomposition'!E9 -> 0.31377412 | C27: =$B27*(1+$B$6)^0 -> 0.31377412 | D27: =$B27*(1+$B$6)^1 -> 0.35456475 | E27: =$B27*(1+$B$6)^2 -> 0.40065817 | F27: =$B27*(1+$B$6)^3 -> 0.45274374 | G27: =$B27*(1+$B$6)^4 -> 0.51160042 | H27: =$B27*(1+$B$6)^5 -> 0.57810848 | I27: =$B27*(1+$B$6)^6 -> 0.65326258 | J27: =$B27*(1+$B$6)^7 -> 0.73818671 | K27: =$B27*(1+$B$6)^8 -> 0.83415099 | L27: =$B27*(1+$B$6)^9 -> 0.94259061 | M27: =$B27*(1+$B$6)^10 -> 1.0651274 | N27: =$B27*(1+$B$6)^11 -> 1.203594 | O27: {=IFERROR(INDEX($C$22:$N$22,MATCH(TRUE(),INDEX(C27:N27>=1,0),0)),"—")} -> 2034
A28: ='2. WCI Decomposition'!A10 -> Wisconsin Site | B28: ='2. WCI Decomposition'!E10 -> 0.26565 | C28: =$B28*(1+$B$6)^0 -> 0.26565 | D28: =$B28*(1+$B$6)^1 -> 0.3001845 | E28: =$B28*(1+$B$6)^2 -> 0.33920848 | F28: =$B28*(1+$B$6)^3 -> 0.38330559 | G28: =$B28*(1+$B$6)^4 -> 0.43313531 | H28: =$B28*(1+$B$6)^5 -> 0.48944291 | I28: =$B28*(1+$B$6)^6 -> 0.55307048 | J28: =$B28*(1+$B$6)^7 -> 0.62496965 | K28: =$B28*(1+$B$6)^8 -> 0.7062157 | L28: =$B28*(1+$B$6)^9 -> 0.79802374 | M28: =$B28*(1+$B$6)^10 -> 0.90176683 | N28: =$B28*(1+$B$6)^11 -> 1.0189965 | O28: {=IFERROR(INDEX($C$22:$N$22,MATCH(TRUE(),INDEX(C28:N28>=1,0),0)),"—")} -> 2035
A29: ='2. WCI Decomposition'!A11 -> Botetourt County | B29: ='2. WCI Decomposition'!E11 -> 0.1375 | C29: =$B29*(1+$B$6)^0 -> 0.1375 | D29: =$B29*(1+$B$6)^1 -> 0.155375 | E29: =$B29*(1+$B$6)^2 -> 0.17557375 | F29: =$B29*(1+$B$6)^3 -> 0.19839834 | G29: =$B29*(1+$B$6)^4 -> 0.22419012 | H29: =$B29*(1+$B$6)^5 -> 0.25333484 | I29: =$B29*(1+$B$6)^6 -> 0.28626837 | J29: =$B29*(1+$B$6)^7 -> 0.32348325 | K29: =$B29*(1+$B$6)^8 -> 0.36553608 | L29: =$B29*(1+$B$6)^9 -> 0.41305577 | M29: =$B29*(1+$B$6)^10 -> 0.46675302 | N29: =$B29*(1+$B$6)^11 -> 0.52743091 | O29: {=IFERROR(INDEX($C$22:$N$22,MATCH(TRUE(),INDEX(C29:N29>=1,0),0)),"—")} -> —
A30: ='2. WCI Decomposition'!A12 -> Memphis | B30: ='2. WCI Decomposition'!E12 -> 0.013430233 | C30: =$B30*(1+$B$6)^0 -> 0.013430233 | D30: =$B30*(1+$B$6)^1 -> 0.015176163 | E30: =$B30*(1+$B$6)^2 -> 0.017149064 | F30: =$B30*(1+$B$6)^3 -> 0.019378442 | G30: =$B30*(1+$B$6)^4 -> 0.02189764 | H30: =$B30*(1+$B$6)^5 -> 0.024744333 | I30: =$B30*(1+$B$6)^6 -> 0.027961096 | J30: =$B30*(1+$B$6)^7 -> 0.031596039 | K30: =$B30*(1+$B$6)^8 -> 0.035703524 | L30: =$B30*(1+$B$6)^9 -> 0.040344982 | M30: =$B30*(1+$B$6)^10 -> 0.045589829 | N30: =$B30*(1+$B$6)^11 -> 0.051516507 | O30: {=IFERROR(INDEX($C$22:$N$22,MATCH(TRUE(),INDEX(C30:N30>=1,0),0)),"—")} -> —
A31: ='2. WCI Decomposition'!A13 -> Midlothian | B31: ='2. WCI Decomposition'!E13 -> 0.034666194 | C31: =$B31*(1+$B$6)^0 -> 0.034666194 | D31: =$B31*(1+$B$6)^1 -> 0.0391728 | E31: =$B31*(1+$B$6)^2 -> 0.044265264 | F31: =$B31*(1+$B$6)^3 -> 0.050019748 | G31: =$B31*(1+$B$6)^4 -> 0.056522315 | H31: =$B31*(1+$B$6)^5 -> 0.063870216 | I31: =$B31*(1+$B$6)^6 -> 0.072173344 | J31: =$B31*(1+$B$6)^7 -> 0.081555879 | K31: =$B31*(1+$B$6)^8 -> 0.092158143 | L31: =$B31*(1+$B$6)^9 -> 0.1041387 | M31: =$B31*(1+$B$6)^10 -> 0.11767673 | N31: =$B31*(1+$B$6)^11 -> 0.13297471 | O31: {=IFERROR(INDEX($C$22:$N$22,MATCH(TRUE(),INDEX(C31:N31>=1,0),0)),"—")} -> —
A32: ='2. WCI Decomposition'!A14 -> Henderson | B32: ='2. WCI Decomposition'!E14 -> 0.001576947 | C32: =$B32*(1+$B$6)^0 -> 0.001576947 | D32: =$B32*(1+$B$6)^1 -> 0.0017819501 | E32: =$B32*(1+$B$6)^2 -> 0.0020136036 | F32: =$B32*(1+$B$6)^3 -> 0.0022753721 | G32: =$B32*(1+$B$6)^4 -> 0.0025711704 | H32: =$B32*(1+$B$6)^5 -> 0.0029054226 | I32: =$B32*(1+$B$6)^6 -> 0.0032831275 | J32: =$B32*(1+$B$6)^7 -> 0.0037099341 | K32: =$B32*(1+$B$6)^8 -> 0.0041922255 | L32: =$B32*(1+$B$6)^9 -> 0.0047372148 | M32: =$B32*(1+$B$6)^10 -> 0.0053530528 | N32: =$B32*(1+$B$6)^11 -> 0.0060489496 | O32: {=IFERROR(INDEX($C$22:$N$22,MATCH(TRUE(),INDEX(C32:N32>=1,0),0)),"—")} -> —

Sheet 5. Ranked Summary
A1: Sheet 5 — Ranked Summary of Ten Sites
A2: Single-row-per-site reference. Rows are positionally ordered by unsorted source; see column I (WCI) to rank descending.
A4: Rank | B4: Site | C4: State | D4: Operator | E4: K (MGD) | F4: W/K | G4: r | H4: PF | I4: WCI | J4: WCI (%) | K4: C_avg/K (%) | L4: Household equivalent | M4: DC / Community (%) | N4: Classification | O4: Yrs to 100% (13% CAGR)
A5: 1 | B5: ='1. Inputs'!A5 -> Lebanon | C5: ='1. Inputs'!B5 -> IN | D5: ='1. Inputs'!C5 -> Meta | E5: ='1. Inputs'!I5 -> 4.6 | F5: ='2. WCI Decomposition'!B5 -> 0.27608696 | G5: ='2. WCI Decomposition'!C5 -> 0.77 | H5: ='2. WCI Decomposition'!D5 -> 6.3 | I5: ='2. WCI Decomposition'!E5 -> 1.3392978 | J5: ='2. WCI Decomposition'!E5 -> 1.3392978 | K5: ='2. WCI Decomposition'!G5 -> 0.21258696 | L5: ='3. Community Equivalence'!D5 -> 3261.1314 | M5: ='3. Community Equivalence'!H5 -> 0.67872249 | N5: ='2. WCI Decomposition'!I5 -> OVERLOAD | O5: =IF(ISNUMBER('4. Growth Projections'!O23),'4. Growth Projections'!O23-2024,"—") -> 0
A6: 2 | B6: ='1. Inputs'!A6 -> Council Bluffs | C6: ='1. Inputs'!B6 -> IA | D6: ='1. Inputs'!C6 -> Google | E6: ='1. Inputs'!I6 -> 30 | F6: ='2. WCI Decomposition'!B6 -> 0.12870724 | G6: ='2. WCI Decomposition'!C6 -> 0.716 | H6: ='2. WCI Decomposition'!D6 -> 6.5 | I6: ='2. WCI Decomposition'!E6 -> 0.5990035 | J6: ='2. WCI Decomposition'!E6 -> 0.5990035 | K6: ='2. WCI Decomposition'!G6 -> 0.092154384 | L6: ='3. Community Equivalence'!D6 -> 9219.5794 | M6: ='3. Community Equivalence'!H6 -> 0.54823531 | N6: ='2. WCI Decomposition'!I6 -> SEVERE | O6: =IF(ISNUMBER('4. Growth Projections'!O24),'4. Growth Projections'!O24-2024,"—") -> 5
A7: 3 | B7: ='1. Inputs'!A7 -> Mayes County | C7: ='1. Inputs'!B7 -> OK | D7: ='1. Inputs'!C7 -> Google | E7: ='1. Inputs'!I7 -> 10 | F7: ='2. WCI Decomposition'!B7 -> 0.30343818 | G7: ='2. WCI Decomposition'!C7 -> 0.752 | H7: ='2. WCI Decomposition'!D7 -> 2.5 | I7: ='2. WCI Decomposition'!E7 -> 0.57046378 | J7: ='2. WCI Decomposition'!E7 -> 0.57046378 | K7: ='2. WCI Decomposition'!G7 -> 0.22818551 | L7: ='3. Community Equivalence'!D7 -> 7609.6015 | M7: ='3. Community Equivalence'!H7 -> 0.69530364 | N7: ='2. WCI Decomposition'!I7 -> SEVERE | O7: =IF(ISNUMBER('4. Growth Projections'!O25),'4. Growth Projections'!O25-2024,"—") -> 5
A8: 4 | B8: ='1. Inputs'!A8 -> The Dalles | C8: ='1. Inputs'!B8 -> OR | D8: ='1. Inputs'!C8 -> Google | E8: ='1. Inputs'!I8 -> 4.5 | F8: ='2. WCI Decomposition'!B8 -> 0.28054607 | G8: ='2. WCI Decomposition'!C8 -> 0.784 | H8: ='2. WCI Decomposition'!D8 -> 2.21 | I8: ='2. WCI Decomposition'!E8 -> 0.48608534 | J8: ='2. WCI Decomposition'!E8 -> 0.48608534 | K8: ='2. WCI Decomposition'!G8 -> 0.21994812 | L8: ='3. Community Equivalence'!D8 -> 3300.7043 | M8: ='3. Community Equivalence'!H8 -> 0.77282841 | N8: ='2. WCI Decomposition'!I8 -> HIGH | O8: =IF(ISNUMBER('4. Growth Projections'!O26),'4. Growth Projections'!O26-2024,"—") -> 6
A9: 5 | B9: ='1. Inputs'!A9 -> Douglas County | C9: ='1. Inputs'!B9 -> GA | D9: ='1. Inputs'!C9 -> Google | E9: ='1. Inputs'!I9 -> 8 | F9: ='2. WCI Decomposition'!B9 -> 0.15194873 | G9: ='2. WCI Decomposition'!C9 -> 0.826 | H9: ='2. WCI Decomposition'!D9 -> 2.5 | I9: ='2. WCI Decomposition'!E9 -> 0.31377412 | J9: ='2. WCI Decomposition'!E9 -> 0.31377412 | K9: ='2. WCI Decomposition'!G9 -> 0.12550965 | L9: ='3. Community Equivalence'!D9 -> 3348.4279 | M9: ='3. Community Equivalence'!H9 -> 0.085918075 | N9: ='2. WCI Decomposition'!I9 -> HIGH | O9: =IF(ISNUMBER('4. Growth Projections'!O27),'4. Growth Projections'!O27-2024,"—") -> 10
A10: 6 | B10: ='1. Inputs'!A10 -> Wisconsin Site | C10: ='1. Inputs'!B10 -> WI | D10: ='1. Inputs'!C10 -> Microsoft | E10: ='1. Inputs'!I10 -> 2 | F10: ='2. WCI Decomposition'!B10 -> 0.0115 | G10: ='2. WCI Decomposition'!C10 -> 0.77 | H10: ='2. WCI Decomposition'!D10 -> 30 | I10: ='2. WCI Decomposition'!E10 -> 0.26565 | J10: ='2. WCI Decomposition'!E10 -> 0.26565 | K10: ='2. WCI Decomposition'!G10 -> 0.008855 | L10: ='3. Community Equivalence'!D10 -> 59.05986 | M10: ='3. Community Equivalence'!H10 -> 0.018437737 | N10: ='2. WCI Decomposition'!I10 -> HIGH | O10: =IF(ISNUMBER('4. Growth Projections'!O28),'4. Growth Projections'!O28-2024,"—") -> 11
A11: 7 | B11: ='1. Inputs'!A11 -> Botetourt County | C11: ='1. Inputs'!B11 -> VA | D11: ='1. Inputs'!C11 -> Google | E11: ='1. Inputs'!I11 -> 28 | F11: ='2. WCI Decomposition'!B11 -> 0.071428571 | G11: ='2. WCI Decomposition'!C11 -> 0.77 | H11: ='2. WCI Decomposition'!D11 -> 2.5 | I11: ='2. WCI Decomposition'!E11 -> 0.1375 | J11: ='2. WCI Decomposition'!E11 -> 0.1375 | K11: ='2. WCI Decomposition'!G11 -> 0.055 | L11: ='3. Community Equivalence'!D11 -> 5135.64 | M11: ='3. Community Equivalence'!H11 -> 0.56586405 | N11: ='2. WCI Decomposition'!I11 -> MODERATE | O11: =IF(ISNUMBER('4. Growth Projections'!O29),'4. Growth Projections'!O29-2024,"—") -> —
A12: 9 | B12: ='1. Inputs'!A12 -> Memphis | C12: ='1. Inputs'!B12 -> TN | D12: ='1. Inputs'!C12 -> xAI | E12: ='1. Inputs'!I12 -> 258 | F12: ='2. WCI Decomposition'!B12 -> 0.003875969 | G12: ='2. WCI Decomposition'!C12 -> 0.77 | H12: ='2. WCI Decomposition'!D12 -> 4.5 | I12: ='2. WCI Decomposition'!E12 -> 0.013430233 | J12: ='2. WCI Decomposition'!E12 -> 0.013430233 | K12: ='2. WCI Decomposition'!G12 -> 0.0029844961 | L12: ='3. Community Equivalence'!D12 -> 2567.82 | M12: ='3. Community Equivalence'!H12 -> 0.015269347 | N12: ='2. WCI Decomposition'!I12 -> MINIMAL | O12: =IF(ISNUMBER('4. Growth Projections'!O30),'4. Growth Projections'!O30-2024,"—") -> —
A13: 8 | B13: ='1. Inputs'!A13 -> Midlothian | C13: ='1. Inputs'!B13 -> TX | D13: ='1. Inputs'!C13 -> Google | E13: ='1. Inputs'!I13 -> 36 | F13: ='2. WCI Decomposition'!B13 -> 0.016807852 | G13: ='2. WCI Decomposition'!C13 -> 0.825 | H13: ='2. WCI Decomposition'!D13 -> 2.5 | I13: ='2. WCI Decomposition'!E13 -> 0.034666194 | J13: ='2. WCI Decomposition'!E13 -> 0.034666194 | K13: ='2. WCI Decomposition'!G13 -> 0.013866478 | L13: ='3. Community Equivalence'!D13 -> 1664.725 | M13: ='3. Community Equivalence'!H13 -> 0.15591179 | N13: ='2. WCI Decomposition'!I13 -> MINIMAL | O13: =IF(ISNUMBER('4. Growth Projections'!O31),'4. Growth Projections'!O31-2024,"—") -> —
A14: 10 | B14: ='1. Inputs'!A14 -> Henderson | C14: ='1. Inputs'!B14 -> NV | D14: ='1. Inputs'!C14 -> Google | E14: ='1. Inputs'!I14 -> 900 | F14: ='2. WCI Decomposition'!B14 -> 0.0010951021 | G14: ='2. WCI Decomposition'!C14 -> 0.576 | H14: ='2. WCI Decomposition'!D14 -> 2.5 | I14: ='2. WCI Decomposition'!E14 -> 0.001576947 | J14: ='2. WCI Decomposition'!E14 -> 0.001576947 | K14: ='2. WCI Decomposition'!G14 -> 0.00063077879 | L14: ='3. Community Equivalence'!D14 -> 1893.1867 | M14: ='3. Community Equivalence'!H14 -> 0.02216358 | N14: ='2. WCI Decomposition'!I14 -> MINIMAL | O14: =IF(ISNUMBER('4. Growth Projections'!O32),'4. Growth Projections'!O32-2024,"—") -> —

Sheet 6. Chart Data
A1: Sheet 6 — Visualization
A2: Each block is a self-contained plot range referenced from live calculation sheets.
A4: Block A — WCI and C_avg/K by site (Fig. 3)
A5: Site | B5: WCI (%) | C5: C_avg/K (%)
A6: ='2. WCI Decomposition'!A5 -> Lebanon | B6: ='2. WCI Decomposition'!E5 -> 1.3392978 | C6: ='2. WCI Decomposition'!G5 -> 0.21258696
A7: ='2. WCI Decomposition'!A6 -> Council Bluffs | B7: ='2. WCI Decomposition'!E6 -> 0.5990035 | C7: ='2. WCI Decomposition'!G6 -> 0.092154384
A8: ='2. WCI Decomposition'!A7 -> Mayes County | B8: ='2. WCI Decomposition'!E7 -> 0.57046378 | C8: ='2. WCI Decomposition'!G7 -> 0.22818551
A9: ='2. WCI Decomposition'!A8 -> The Dalles | B9: ='2. WCI Decomposition'!E8 -> 0.48608534 | C9: ='2. WCI Decomposition'!G8 -> 0.21994812
A10: ='2. WCI Decomposition'!A9 -> Douglas County | B10: ='2. WCI Decomposition'!E9 -> 0.31377412 | C10: ='2. WCI Decomposition'!G9 -> 0.12550965
A11: ='2. WCI Decomposition'!A10 -> Wisconsin Site | B11: ='2. WCI Decomposition'!E10 -> 0.26565 | C11: ='2. WCI Decomposition'!G10 -> 0.008855
A12: ='2. WCI Decomposition'!A11 -> Botetourt County | B12: ='2. WCI Decomposition'!E11 -> 0.1375 | C12: ='2. WCI Decomposition'!G11 -> 0.055
A13: ='2. WCI Decomposition'!A12 -> Memphis | B13: ='2. WCI Decomposition'!E12 -> 0.013430233 | C13: ='2. WCI Decomposition'!G12 -> 0.0029844961
A14: ='2. WCI Decomposition'!A13 -> Midlothian | B14: ='2. WCI Decomposition'!E13 -> 0.034666194 | C14: ='2. WCI Decomposition'!G13 -> 0.013866478
A15: ='2. WCI Decomposition'!A14 -> Henderson | B15: ='2. WCI Decomposition'!E14 -> 0.001576947 | C15: ='2. WCI Decomposition'!G14 -> 0.00063077879
A17: Block B — Facility share of community water use (Fig. 3b)
A18: Site | B18: DC / Community (%) | C18: Household equivalent
A19: ='3. Community Equivalence'!A5 -> Lebanon | B19: ='3. Community Equivalence'!H5 -> 0.67872249 | C19: ='3. Community Equivalence'!D5 -> 3261.1314
A20: ='3. Community Equivalence'!A6 -> Council Bluffs | B20: ='3. Community Equivalence'!H6 -> 0.54823531 | C20: ='3. Community Equivalence'!D6 -> 9219.5794
A21: ='3. Community Equivalence'!A7 -> Mayes County | B21: ='3. Community Equivalence'!H7 -> 0.69530364 | C21: ='3. Community Equivalence'!D7 -> 7609.6015
A22: ='3. Community Equivalence'!A8 -> The Dalles | B22: ='3. Community Equivalence'!H8 -> 0.77282841 | C22: ='3. Community Equivalence'!D8 -> 3300.7043
A23: ='3. Community Equivalence'!A9 -> Douglas County | B23: ='3. Community Equivalence'!H9 -> 0.085918075 | C23: ='3. Community Equivalence'!D9 -> 3348.4279
A24: ='3. Community Equivalence'!A10 -> Wisconsin Site | B24: ='3. Community Equivalence'!H10 -> 0.018437737 | C24: ='3. Community Equivalence'!D10 -> 59.05986
A25: ='3. Community Equivalence'!A11 -> Botetourt County | B25: ='3. Community Equivalence'!H11 -> 0.56586405 | C25: ='3. Community Equivalence'!D11 -> 5135.64
A26: ='3. Community Equivalence'!A12 -> Memphis | B26: ='3. Community Equivalence'!H12 -> 0.015269347 | C26: ='3. Community Equivalence'!D12 -> 2567.82
A27: ='3. Community Equivalence'!A13 -> Midlothian | B27: ='3. Community Equivalence'!H13 -> 0.15591179 | C27: ='3. Community Equivalence'!D13 -> 1664.725
A28: ='3. Community Equivalence'!A14 -> Henderson | B28: ='3. Community Equivalence'!H14 -> 0.02216358 | C28: ='3. Community Equivalence'!D14 -> 1893.1867
A30: Block C — Decomposition factors (Fig. 4)
A31: Site | B31: W/K | C31: r | D31: PF | E31: WCI
A32: ='2. WCI Decomposition'!A5 -> Lebanon | B32: ='2. WCI Decomposition'!B5 -> 0.27608696 | C32: ='2. WCI Decomposition'!C5 -> 0.77 | D32: ='2. WCI Decomposition'!D5 -> 6.3 | E32: ='2. WCI Decomposition'!E5 -> 1.3392978
A33: ='2. WCI Decomposition'!A6 -> Council Bluffs | B33: ='2. WCI Decomposition'!B6 -> 0.12870724 | C33: ='2. WCI Decomposition'!C6 -> 0.716 | D33: ='2. WCI Decomposition'!D6 -> 6.5 | E33: ='2. WCI Decomposition'!E6 -> 0.5990035
A34: ='2. WCI Decomposition'!A7 -> Mayes County | B34: ='2. WCI Decomposition'!B7 -> 0.30343818 | C34: ='2. WCI Decomposition'!C7 -> 0.752 | D34: ='2. WCI Decomposition'!D7 -> 2.5 | E34: ='2. WCI Decomposition'!E7 -> 0.57046378
A35: ='2. WCI Decomposition'!A8 -> The Dalles | B35: ='2. WCI Decomposition'!B8 -> 0.28054607 | C35: ='2. WCI Decomposition'!C8 -> 0.784 | D35: ='2. WCI Decomposition'!D8 -> 2.21 | E35: ='2. WCI Decomposition'!E8 -> 0.48608534
A36: ='2. WCI Decomposition'!A9 -> Douglas County | B36: ='2. WCI Decomposition'!B9 -> 0.15194873 | C36: ='2. WCI Decomposition'!C9 -> 0.826 | D36: ='2. WCI Decomposition'!D9 -> 2.5 | E36: ='2. WCI Decomposition'!E9 -> 0.31377412
A37: ='2. WCI Decomposition'!A10 -> Wisconsin Site | B37: ='2. WCI Decomposition'!B10 -> 0.0115 | C37: ='2. WCI Decomposition'!C10 -> 0.77 | D37: ='2. WCI Decomposition'!D10 -> 30 | E37: ='2. WCI Decomposition'!E10 -> 0.26565
A38: ='2. WCI Decomposition'!A11 -> Botetourt County | B38: ='2. WCI Decomposition'!B11 -> 0.071428571 | C38: ='2. WCI Decomposition'!C11 -> 0.77 | D38: ='2. WCI Decomposition'!D11 -> 2.5 | E38: ='2. WCI Decomposition'!E11 -> 0.1375
A39: ='2. WCI Decomposition'!A12 -> Memphis | B39: ='2. WCI Decomposition'!B12 -> 0.003875969 | C39: ='2. WCI Decomposition'!C12 -> 0.77 | D39: ='2. WCI Decomposition'!D12 -> 4.5 | E39: ='2. WCI Decomposition'!E12 -> 0.013430233
A40: ='2. WCI Decomposition'!A13 -> Midlothian | B40: ='2. WCI Decomposition'!B13 -> 0.016807852 | C40: ='2. WCI Decomposition'!C13 -> 0.825 | D40: ='2. WCI Decomposition'!D13 -> 2.5 | E40: ='2. WCI Decomposition'!E13 -> 0.034666194
A41: ='2. WCI Decomposition'!A14 -> Henderson | B41: ='2. WCI Decomposition'!B14 -> 0.0010951021 | C41: ='2. WCI Decomposition'!C14 -> 0.576 | D41: ='2. WCI Decomposition'!D14 -> 2.5 | E41: ='2. WCI Decomposition'!E14 -> 0.001576947
A43: Block D — 13% CAGR trajectories (Figure 5b)
A44: Site | B44: 2024 | C44: 2025 | D44: 2026 | E44: 2027 | F44: 2028 | G44: 2029 | H44: 2030 | I44: 2031 | J44: 2032 | K44: 2033 | L44: 2034 | M44: 2035
...

Sheet 7. Policy Sensitivity
A1: Sheet 7 — Policy Lever Sensitivity
A2: Effect on WCI of three policy levers applied in isolation. Yellow cells are editable targets.
A4: Lever Targets (edit to re-run) | Q4: Figure 5a — plot data
A5: Siting multiplier α | B5: 0.75 | C5: W/K multiplier (0.75 = move facility to a utility 33% larger for the same W). | Q5: Site | R5: Siting Δ | S5: Technology Δ | T5: Management Δ
A6: Technology target r | B6: 0.25 | C6: Target consumptive ratio (0.25 ≈ closed-loop / dry-cooling hybrid). | Q6: ='2. WCI Decomposition'!A5 -> Lebanon | R6: =H10 -> 0.25 | S6: =K10 -> 0.67532468 | T6: =N10 -> 0.68253968
A7: Management target PF | B7: 2 | C7: Target peaking factor (2.0 = well-managed demand-shifted operation). | Q7: ='2. WCI Decomposition'!A6 -> Council Bluffs | R7: =H11 -> 0.25 | S7: =K11 -> 0.65083799 | T7: =N11 -> 0.69230769
Q8: ='2. WCI Decomposition'!A7 -> Mayes County | R8: =H12 -> 0.25 | S8: =K12 -> 0.66755319 | T8: =N12 -> 0.2
A9: Site | B9: Baseline W/K | C9: Baseline r | D9: Baseline PF | E9: Baseline WCI | F9: Siting new WCI | G9: Siting Δ | H9: Siting Δ % | I9: Tech new WCI | J9: Tech Δ | K9: Tech Δ % | L9: Mgmt new WCI | M9: Mgmt Δ | N9: Mgmt Δ % | O9: Dominant lever | Q9: ='2. WCI Decomposition'!A8 -> The Dalles | R9: =H13 -> 0.25 | S9: =K13 -> 0.68112245 | T9: =N13 -> 0.095022624
A10: ='2. WCI Decomposition'!A5 -> Lebanon | B10: ='2. WCI Decomposition'!B5 -> 0.27608696 | C10: ='2. WCI Decomposition'!C5 -> 0.77 | D10: ='2. WCI Decomposition'!D5 -> 6.3 | E10: ='2. WCI Decomposition'!E5 -> 1.3392978 | F10: =B10*$B$5*C10*D10 -> 1.0044734 | G10: =E10-F10 -> 0.33482446 | H10: =IFERROR((E10-F10)/E10,0) -> 0.25 | I10: =B10*MIN(C10,$B$6)*D10 -> 0.43483696 | J10: =E10-I10 -> 0.90446087 | K10: =IFERROR((E10-I10)/E10,0) -> 0.67532468 | L10: =B10*C10*MIN(D10,$B$7) -> 0.42517391 | M10: =E10-L10 -> 0.91412391 | N10: =IFERROR((E10-L10)/E10,0) -> 0.68253968 | O10: =IF(G10=MAX(G10,J10,M10),"Siting",IF(J10=MAX(G10,J10,M10),"Technology","Management")) -> Management | Q10: ='2. WCI Decomposition'!A9 -> Douglas County | R10: =H14 -> 0.25 | S10: =K14 -> 0.69733656 | T10: =N14 -> 0.2
A11: ='2. WCI Decomposition'!A6 -> Council Bluffs | B11: ='2. WCI Decomposition'!B6 -> 0.12870724 | C11: ='2. WCI Decomposition'!C6 -> 0.716 | D11: ='2. WCI Decomposition'!D6 -> 6.5 | E11: ='2. WCI Decomposition'!E6 -> 0.5990035 | F11: =B11*$B$5*C11*D11 -> 0.44925262 | G11: =E11-F11 -> 0.14975087 | H11: =IFERROR((E11-F11)/E11,0) -> 0.25 | I11: =B11*MIN(C11,$B$6)*D11 -> 0.20914927 | J11: =E11-I11 -> 0.38985423 | K11: =IFERROR((E11-I11)/E11,0) -> 0.65083799 | L11: =B11*C11*MIN(D11,$B$7) -> 0.18430877 | M11: =E11-L11 -> 0.41469473 | N11: =IFERROR((E11-L11)/E11,0) -> 0.69230769 | O11: =IF(G11=MAX(G11,J11,M11),"Siting",IF(J11=MAX(G11,J11,M11),"Technology","Management")) -> Management | Q11: ='2. WCI Decomposition'!A10 -> Wisconsin Site | R11: =H15 -> 0.25 | S11: =K15 -> 0.67532468 | T11: =N15 -> 0.93333333
A12: ='2. WCI Decomposition'!A7 -> Mayes County | B12: ='2. WCI Decomposition'!B7 -> 0.30343818 | C12: ='2. WCI Decomposition'!C7 -> 0.752 | D12: ='2. WCI Decomposition'!D7 -> 2.5 | E12: ='2. WCI Decomposition'!E7 -> 0.57046378 | F12: =B12*$B$5*C12*D12 -> 0.42784783 | G12: =E12-F12 -> 0.14261594 | H12: =IFERROR((E12-F12)/E12,0) -> 0.25 | I12: =B12*MIN(C12,$B$6)*D12 -> 0.18964886 | J12: =E12-I12 -> 0.38081492 | K12: =IFERROR((E12-I12)/E12,0) -> 0.66755319 | L12: =B12*C12*MIN(D12,$B$7) -> 0.45637102 | M12: =E12-L12 -> 0.11409276 | N12: =IFERROR((E12-L12)/E12,0) -> 0.2 | O12: =IF(G12=MAX(G12,J12,M12),"Siting",IF(J12=MAX(G12,J12,M12),"Technology","Management")) -> Technology | Q12: ='2. WCI Decomposition'!A11 -> Botetourt County | R12: =H16 -> 0.25 | S12: =K16 -> 0.67532468 | T12: =N16 -> 0.2
A13: ='2. WCI Decomposition'!A8 -> The Dalles | B13: ='2. WCI Decomposition'!B8 -> 0.28054607 | C13: ='2. WCI Decomposition'!C8 -> 0.784 | D13: ='2. WCI Decomposition'!D8 -> 2.21 | E13: ='2. WCI Decomposition'!E8 -> 0.48608534 | F13: =B13*$B$5*C13*D13 -> 0.36456401 | G13: =E13-F13 -> 0.12152134 | H13: =IFERROR((E13-F13)/E13,0) -> 0.25 | I13: =B13*MIN(C13,$B$6)*D13 -> 0.1550017 | J13: =E13-I13 -> 0.33108364 | K13: =IFERROR((E13-I13)/E13,0) -> 0.68112245 | L13: =B13*C13*MIN(D13,$B$7) -> 0.43989624 | M13: =E13-L13 -> 0.046189105 | N13: =IFERROR((E13-L13)/E13,0) -> 0.095022624 | O13: =IF(G13=MAX(G13,J13,M13),"Siting",IF(J13=MAX(G13,J13,M13),"Technology","Management")) -> Technology | Q13: ='2. WCI Decomposition'!A12 -> Memphis | R13: =H17 -> 0.25 | S13: =K17 -> 0.67532468 | T13: =N17 -> 0.55555556
A14: ='2. WCI Decomposition'!A9 -> Douglas County | B14: ='2. WCI Decomposition'!B9 -> 0.15194873 | C14: ='2. WCI Decomposition'!C9 -> 0.826 | D14: ='2. WCI Decomposition'!D9 -> 2.5 | E14: ='2. WCI Decomposition'!E9 -> 0.31377412 | F14: =B14*$B$5*C14*D14 -> 0.23533059 | G14: =E14-F14 -> 0.07844353 | H14: =IFERROR((E14-F14)/E14,0) -> 0.25 | I14: =B14*MIN(C14,$B$6)*D14 -> 0.094967954 | J14: =E14-I14 -> 0.21880617 | K14: =IFERROR((E14-I14)/E14,0) -> 0.69733656 | L14: =B14*C14*MIN(D14,$B$7) -> 0.2510193 | M14: =E14-L14 -> 0.062754824 | N14: =IFERROR((E14-L14)/E14,0) -> 0.2 | O14: =IF(G14=MAX(G14,J14,M14),"Siting",IF(J14=MAX(G14,J14,M14),"Technology","Management")) -> Technology | Q14: ='2. WCI Decomposition'!A13 -> Midlothian | R14: =H18 -> 0.25 | S14: =K18 -> 0.6969697 | T14: =N18 -> 0.2
A15: ='2. WCI Decomposition'!A10 -> Wisconsin Site | B15: ='2. WCI Decomposition'!B10 -> 0.0115 | C15: ='2. WCI Decomposition'!C10 -> 0.77 | D15: ='2. WCI Decomposition'!D10 -> 30 | E15: ='2. WCI Decomposition'!E10 -> 0.26565 | F15: =B15*$B$5*C15*D15 -> 0.1992375 | G15: =E15-F15 -> 0.0664125 | H15: =IFERROR((E15-F15)/E15,0) -> 0.25 | I15: =B15*MIN(C15,$B$6)*D15 -> 0.08625 | J15: =E15-I15 -> 0.1794 | K15: =IFERROR((E15-I15)/E15,0) -> 0.67532468 | L15: =B15*C15*MIN(D15,$B$7) -> 0.01771 | M15: =E15-L15 -> 0.24794 | N15: =IFERROR((E15-L15)/E15,0) -> 0.93333333 | O15: =IF(G15=MAX(G15,J15,M15),"Siting",IF(J15=MAX(G15,J15,M15),"Technology","Management")) -> Management | Q15: ='2. WCI Decomposition'!A14 -> Henderson | R15: =H19 -> 0.25 | S15: =K19 -> 0.56597222 | T15: =N19 -> 0.2
A16: ='2. WCI Decomposition'!A11 -> Botetourt County | B16: ='2. WCI Decomposition'!B11 -> 0.071428571 | C16: ='2. WCI Decomposition'!C11 -> 0.77 | D16: ='2. WCI Decomposition'!D11 -> 2.5 | E16: ='2. WCI Decomposition'!E11 -> 0.1375 | F16: =B16*$B$5*C16*D16 -> 0.103125 | G16: =E16-F16 -> 0.034375 | H16: =IFERROR((E16-F16)/E16,0) -> 0.25 | I16: =B16*MIN(C16,$B$6)*D16 -> 0.044642857 | J16: =E16-I16 -> 0.092857143 | K16: =IFERROR((E16-I16)/E16,0) -> 0.67532468 | L16: =B16*C16*MIN(D16,$B$7) -> 0.11 | M16: =E16-L16 -> 0.0275 | N16: =IFERROR((E16-L16)/E16,0) -> 0.2 | O16: =IF(G16=MAX(G16,J16,M16),"Siting",IF(J16=MAX(G16,J16,M16),"Technology","Management")) -> Technology
A17: ='2. WCI Decomposition'!A12 -> Memphis | B17: ='2. WCI Decomposition'!B12 -> 0.003875969 | C17: ='2. WCI Decomposition'!C12 -> 0.77 | D17: ='2. WCI Decomposition'!D12 -> 4.5 | E17: ='2. WCI Decomposition'!E12 -> 0.013430233 | F17: =B17*$B$5*C17*D17 -> 0.010072674 | G17: =E17-F17 -> 0.0033575581 | H17: =IFERROR((E17-F17)/E17,0) -> 0.25 | I17: =B17*MIN(C17,$B$6)*D17 -> 0.0043604651 | J17: =E17-I17 -> 0.0090697674 | K17: =IFERROR((E17-I17)/E17,0) -> 0.67532468 | L17: =B17*C17*MIN(D17,$B$7) -> 0.0059689922 | M17: =E17-L17 -> 0.0074612403 | N17: =IFERROR((E17-L17)/E17,0) -> 0.55555556 | O17: =IF(G17=MAX(G17,J17,M17),"Siting",IF(J17=MAX(G17,J17,M17),"Technology","Management")) -> Technology
A18: ='2. WCI Decomposition'!A13 -> Midlothian | B18: ='2. WCI Decomposition'!B13 -> 0.016807852 | C18: ='2. WCI Decomposition'!C13 -> 0.825 | D18: ='2. WCI Decomposition'!D13 -> 2.5 | E18: ='2. WCI Decomposition'!E13 -> 0.034666194 | F18: =B18*$B$5*C18*D18 -> 0.025999646 | G18: =E18-F18 -> 0.0086665486 | H18: =IFERROR((E18-F18)/E18,0) -> 0.25 | I18: =B18*MIN(C18,$B$6)*D18 -> 0.010504907 | J18: =E18-I18 -> 0.024161287 | K18: =IFERROR((E18-I18)/E18,0) -> 0.6969697 | L18: =B18*C18*MIN(D18,$B$7) -> 0.027732955 | M18: =E18-L18 -> 0.0069332389 | N18: =IFERROR((E18-L18)/E18,0) -> 0.2 | O18: =IF(G18=MAX(G18,J18,M18),"Siting",IF(J18=MAX(G18,J18,M18),"Technology","Management")) -> Technology
A19: ='2. WCI Decomposition'!A14 -> Henderson | B19: ='2. WCI Decomposition'!B14 -> 0.0010951021 | C19: ='2. WCI Decomposition'!C14 -> 0.576 | D19: ='2. WCI Decomposition'!D14 -> 2.5 | E19: ='2. WCI Decomposition'!E14 -> 0.001576947 | F19: =B19*$B$5*C19*D19 -> 0.0011827102 | G19: =E19-F19 -> 0.00039423674 | H19: =IFERROR((E19-F19)/E19,0) -> 0.25 | I19: =B19*MIN(C19,$B$6)*D19 -> 0.00068443879 | J19: =E19-I19 -> 0.00089250818 | K19: =IFERROR((E19-I19)/E19,0) -> 0.56597222 | L19: =B19*C19*MIN(D19,$B$7) -> 0.0012615576 | M19: =E19-L19 -> 0.00031538939 | N19: =IFERROR((E19-L19)/E19,0) -> 0.2 | O19: =IF(G19=MAX(G19,J19,M19),"Siting",IF(J19=MAX(G19,J19,M19),"Technology","Management")) -> Technology
A21: Interpretation Notes
A22: • Each lever is applied to one factor only, holding the other two at their current values. This isolates the marginal benefit of the lever and is conservative relative to any combined intervention.
A23: • MIN() guards ensure that a site already performing better than the target on a given factor is not penalised (new WCI ≤ baseline by construction).
A24: • The Siting lever is modelled as a W/K multiplier because physical relocation and utility capacity expansion are interchangeable for the purposes of the ratio.
A25: • The dominant lever column indicates which intervention delivers the largest absolute WCI reduction for each site; this is actionable policy guidance derived mechanically from the decomposition.
A26: • For sites already classified MINIMAL or LOW (Memphis, Mesa, Henderson), all levers produce only marginal gains; intervention should be directed elsewhere.
